<?xml version="1.0" encoding="utf-8"?>
<!-- This URDF was automatically created by SolidWorks to URDF Exporter! Originally created by Stephen Brawner (brawner@gmail.com) 
     Commit Version: 1.6.0-1-g15f4949  Build Version: 1.6.7594.29634
     For more information, please see http://wiki.ros.org/sw_urdf_exporter -->
<robot
  name="总装.SLDASM">
  <link
    name="base_link">
    <inertial>
      <origin
        xyz="0.058507 -0.29935 -0.31485"
        rpy="0 0 0" />
      <mass
        value="0.0080158" />
      <inertia
        ixx="9.653E-06"
        ixy="-1.038E-23"
        ixz="-7.4106E-19"
        iyy="1.9301E-05"
        iyz="6.9312E-24"
        izz="9.653E-06" />
    </inertial>
    <visual>
      <origin
        xyz="0 0 0"
        rpy="0 0 0" />
      <geometry>
        <mesh
          filename="package://总装.SLDASM/meshes/base_link.STL" />
      </geometry>
      <material
        name="">
        <color
          rgba="0.79216 0.81961 0.93333 1" />
      </material>
    </visual>
    <collision>
      <origin
        xyz="0 0 0"
        rpy="0 0 0" />
      <geometry>
        <mesh
          filename="package://总装.SLDASM/meshes/base_link.STL" />
      </geometry>
    </collision>
  </link>
  <link
    name="link1">
    <inertial>
      <origin
        xyz="0.032984 -1.0041E-05 0.010424"
        rpy="0 0 0" />
      <mass
        value="0.32538" />
      <inertia
        ixx="0.00018153"
        ixy="-9.7293E-06"
        ixz="4.0127E-08"
        iyy="0.00019741"
        iyz="1.7813E-08"
        izz="0.00032826" />
    </inertial>
    <visual>
      <origin
        xyz="0 0 0"
        rpy="0 0 0" />
      <geometry>
        <mesh
          filename="package://总装.SLDASM/meshes/link1.STL" />
      </geometry>
      <material
        name="">
        <color
          rgba="0.29412 0.29412 0.29412 1" />
      </material>
    </visual>
    <collision>
      <origin
        xyz="0 0 0"
        rpy="0 0 0" />
      <geometry>
        <mesh
          filename="package://总装.SLDASM/meshes/link1.STL" />
      </geometry>
    </collision>
  </link>
  <joint
    name="joint1"
    type="continuous">
    <origin
      xyz="0.088416 0.32879 -0.26535"
      rpy="-3.1416 0 -2.7053" />
    <parent
      link="base_link" />
    <child
      link="link1" />
    <axis
      xyz="0 0 0" />
  </joint>
  <link
    name="link2">
    <inertial>
      <origin
        xyz="0.032868 0.00022865 0.014604"
        rpy="0 0 0" />
      <mass
        value="0.2712" />
      <inertia
        ixx="0.00016671"
        ixy="2.658E-07"
        ixz="4.0127E-08"
        iyy="0.00016582"
        iyz="1.7813E-08"
        izz="0.00028189" />
    </inertial>
    <visual>
      <origin
        xyz="0 0 0"
        rpy="0 0 0" />
      <geometry>
        <mesh
          filename="package://总装.SLDASM/meshes/link2.STL" />
      </geometry>
      <material
        name="">
        <color
          rgba="0.29412 0.29412 0.29412 1" />
      </material>
    </visual>
    <collision>
      <origin
        xyz="0 0 0"
        rpy="0 0 0" />
      <geometry>
        <mesh
          filename="package://总装.SLDASM/meshes/link2.STL" />
      </geometry>
    </collision>
  </link>
  <joint
    name="joint2"
    type="continuous">
    <origin
      xyz="0.053344 0.027141 -0.078446"
      rpy="-1.5708 -0.43633 -2.7053" />
    <parent
      link="link1" />
    <child
      link="link2" />
    <axis
      xyz="0 0 0" />
  </joint>
  <link
    name="link3">
    <inertial>
      <origin
        xyz="0.032981 -1.1589E-05 0.013651"
        rpy="0 0 0" />
      <mass
        value="0.2819" />
      <inertia
        ixx="0.00016852"
        ixy="-2.7771E-06"
        ixz="4.0127E-08"
        iyy="0.00017273"
        iyz="1.7813E-08"
        izz="0.00029061" />
    </inertial>
    <visual>
      <origin
        xyz="0 0 0"
        rpy="0 0 0" />
      <geometry>
        <mesh
          filename="package://总装.SLDASM/meshes/link3.STL" />
      </geometry>
      <material
        name="">
        <color
          rgba="0.29412 0.29412 0.29412 1" />
      </material>
    </visual>
    <collision>
      <origin
        xyz="0 0 0"
        rpy="0 0 0" />
      <geometry>
        <mesh
          filename="package://总装.SLDASM/meshes/link3.STL" />
      </geometry>
    </collision>
  </link>
  <joint
    name="joint3"
    type="continuous">
    <origin
      xyz="-0.13105 0.38481 0.0295"
      rpy="3.1416 0 2.4435" />
    <parent
      link="link2" />
    <child
      link="link3" />
    <axis
      xyz="0 0 0" />
  </joint>
  <link
    name="link4">
    <inertial>
      <origin
        xyz="0.49209 -0.0046427 0.15301"
        rpy="0 0 0" />
      <mass
        value="0.090661" />
      <inertia
        ixx="5.0218E-05"
        ixy="-3.5693E-06"
        ixz="4.9182E-09"
        iyy="4.9595E-05"
        iyz="-1.0572E-08"
        izz="9.5414E-05" />
    </inertial>
    <visual>
      <origin
        xyz="0 0 0"
        rpy="0 0 0" />
      <geometry>
        <mesh
          filename="package://总装.SLDASM/meshes/link4.STL" />
      </geometry>
      <material
        name="">
        <color
          rgba="1 1 0 1" />
      </material>
    </visual>
    <collision>
      <origin
        xyz="0 0 0"
        rpy="0 0 0" />
      <geometry>
        <mesh
          filename="package://总装.SLDASM/meshes/link4.STL" />
      </geometry>
    </collision>
  </link>
  <joint
    name="joint4"
    type="continuous">
    <origin
      xyz="0.28279 0.27987 -0.41563"
      rpy="-1.5708 -0.7854 -2.7053" />
    <parent
      link="link3" />
    <child
      link="link4" />
    <axis
      xyz="0 0 0" />
  </joint>
  <link
    name="link5">
    <inertial>
      <origin
        xyz="0.49209 -0.0046427 0.15301"
        rpy="0 0 0" />
      <mass
        value="0.090661" />
      <inertia
        ixx="5.0218E-05"
        ixy="-3.5693E-06"
        ixz="4.9127E-09"
        iyy="4.9595E-05"
        iyz="-1.0566E-08"
        izz="9.5414E-05" />
    </inertial>
    <visual>
      <origin
        xyz="0 0 0"
        rpy="0 0 0" />
      <geometry>
        <mesh
          filename="package://总装.SLDASM/meshes/link5.STL" />
      </geometry>
      <material
        name="">
        <color
          rgba="1 1 0 1" />
      </material>
    </visual>
    <collision>
      <origin
        xyz="0 0 0"
        rpy="0 0 0" />
      <geometry>
        <mesh
          filename="package://总装.SLDASM/meshes/link5.STL" />
      </geometry>
    </collision>
  </link>
  <joint
    name="joint5"
    type="continuous">
    <origin
      xyz="0.84031 0.13456 0.87568"
      rpy="1.5708 0.7854 -2.3562" />
    <parent
      link="link4" />
    <child
      link="link5" />
    <axis
      xyz="0 0 0" />
  </joint>
  <link
    name="link6">
    <inertial>
      <origin
        xyz="0.49209 -0.0046417 0.15301"
        rpy="0 0 0" />
      <mass
        value="0.090659" />
      <inertia
        ixx="5.3759E-05"
        ixy="-2.6828E-08"
        ixz="5.0363E-09"
        iyy="4.6053E-05"
        iyz="-1.1008E-08"
        izz="9.5413E-05" />
    </inertial>
    <visual>
      <origin
        xyz="0 0 0"
        rpy="0 0 0" />
      <geometry>
        <mesh
          filename="package://总装.SLDASM/meshes/link6.STL" />
      </geometry>
      <material
        name="">
        <color
          rgba="1 1 0 1" />
      </material>
    </visual>
    <collision>
      <origin
        xyz="0 0 0"
        rpy="0 0 0" />
      <geometry>
        <mesh
          filename="package://总装.SLDASM/meshes/link6.STL" />
      </geometry>
    </collision>
  </link>
  <joint
    name="joint6"
    type="continuous">
    <origin
      xyz="0.24881 -0.45717 0.21976"
      rpy="-1.5708 0 0.7854" />
    <parent
      link="link5" />
    <child
      link="link6" />
    <axis
      xyz="0 0 0" />
  </joint>
</robot>